Traceback (most recent call last):
  File "/opt/homebrew/lib/python3.11/site-packages/jupyter_cache/executors/utils.py", line 58, in single_nb_execution
    executenb(
  File "/opt/homebrew/lib/python3.11/site-packages/nbclient/client.py", line 1305, in execute
    return NotebookClient(nb=nb, resources=resources, km=km, **kwargs).execute()
           ^^^^^^^^^^^^^^^^^^^^^^^^^^^^^^^^^^^^^^^^^^^^^^^^^^^^^^^^^^^^^^^^^^^^^
  File "/opt/homebrew/lib/python3.11/site-packages/jupyter_core/utils/__init__.py", line 166, in wrapped
    return loop.run_until_complete(inner)
           ^^^^^^^^^^^^^^^^^^^^^^^^^^^^^^
  File "/opt/homebrew/Cellar/python@3.11/3.11.5/Frameworks/Python.framework/Versions/3.11/lib/python3.11/asyncio/base_events.py", line 653, in run_until_complete
    return future.result()
           ^^^^^^^^^^^^^^^
  File "/opt/homebrew/lib/python3.11/site-packages/nbclient/client.py", line 705, in async_execute
    await self.async_execute_cell(
  File "/opt/homebrew/lib/python3.11/site-packages/nbclient/client.py", line 1058, in async_execute_cell
    await self._check_raise_for_error(cell, cell_index, exec_reply)
  File "/opt/homebrew/lib/python3.11/site-packages/nbclient/client.py", line 914, in _check_raise_for_error
    raise CellExecutionError.from_cell_and_msg(cell, exec_reply_content)
nbclient.exceptions.CellExecutionError: An error occurred while executing the following cell:
------------------
from sahi.predict import get_sliced_prediction
from sahi import AutoDetectionModel

from sahi.utils.yolov8 import download_yolov8s_model
from sahi.utils.cv import read_image
from sahi.utils.file import download_from_url

from IPython.display import Image

# Download sample image
download_from_url('https://raw.githubusercontent.com/obss/sahi/main/demo/demo_data/small-vehicles1.jpeg', 'small-vehicles1.jpeg')

# Download YOLOv8 weights
model_path='yolov8s.pt'
download_yolov8s_model(model_path)

# Build YOLOv8 detector
detection_model = AutoDetectionModel.from_pretrained(
    model_type='yolov8', 
    model_path=model_path, 
    confidence_threshold=0.3,
    device='cpu'
)

# Perform sliced inference
result = get_sliced_prediction(
    read_image("small-vehicles1.jpeg"),
    detection_model,
    slice_height=256,
    slice_width=256,
    overlap_height_ratio=0.2,
    overlap_width_ratio=0.2
)

# Save and display results
result.export_visuals(export_dir="./")
Image("./prediction_visual.png")
------------------


[0;31m---------------------------------------------------------------------------[0m
[0;31mModuleNotFoundError[0m                       Traceback (most recent call last)
Cell [0;32mIn[1], line 1[0m
[0;32m----> 1[0m [38;5;28;01mfrom[39;00m [38;5;21;01msahi[39;00m[38;5;21;01m.[39;00m[38;5;21;01mpredict[39;00m [38;5;28;01mimport[39;00m get_sliced_prediction
[1;32m      2[0m [38;5;28;01mfrom[39;00m [38;5;21;01msahi[39;00m [38;5;28;01mimport[39;00m AutoDetectionModel
[1;32m      4[0m [38;5;28;01mfrom[39;00m [38;5;21;01msahi[39;00m[38;5;21;01m.[39;00m[38;5;21;01mutils[39;00m[38;5;21;01m.[39;00m[38;5;21;01myolov8[39;00m [38;5;28;01mimport[39;00m download_yolov8s_model

[0;31mModuleNotFoundError[0m: No module named 'sahi'

